Traceback (most recent call last):
  File "/Users/tinghui/workspace/github/DTU02476-Machine-Learning-Operations/env/lib/python3.11/site-packages/wandb/sdk/wandb_config.py", line 163, in __getattr__
    return self.__getitem__(key)
           ^^^^^^^^^^^^^^^^^^^^^
  File "/Users/tinghui/workspace/github/DTU02476-Machine-Learning-Operations/env/lib/python3.11/site-packages/wandb/sdk/wandb_config.py", line 130, in __getitem__
    return self._items[key]
           ~~~~~~~~~~~^^^^^
KeyError: 'dataset_path'
The above exception was the direct cause of the following exception:
Traceback (most recent call last):
  File "/Users/tinghui/workspace/github/DTU02476-Machine-Learning-Operations/s4_debugging_and_logging/sweep_exercise/vae_mnist_working.py", line 173, in <module>
    train()
  File "/Users/tinghui/workspace/github/DTU02476-Machine-Learning-Operations/s4_debugging_and_logging/sweep_exercise/vae_mnist_working.py", line 97, in train
    dataset_path = config.dataset_path
                   ^^^^^^^^^^^^^^^^^^^
  File "/Users/tinghui/workspace/github/DTU02476-Machine-Learning-Operations/env/lib/python3.11/site-packages/wandb/sdk/wandb_config.py", line 165, in __getattr__
    raise AttributeError(
AttributeError: <class 'wandb.sdk.wandb_config.Config'> object has no attribute 'dataset_path'